Workbook

Sheet Alloy quote
A1: First Mile Group, Inc. d/b/a Alloy: auto-renewal quote, May 2025
A2: Reconstructed from m3ter. Blue: values held in m3ter. Black: formulas. Green: formulas reading another tab. Yellow: illustrative, not held in m3ter.
A3: Source: m3ter data in local Postgres (customerdb, schema entrust), queried by Claude on 7 Oct 2026. The queries are on the Data Sources tab.
A4: Customer | B4: First Mile Group, Inc. d/b/a Alloy
A5: m3ter account code | B5: 00124000018txRVAAY
A6: Salesforce opportunity | B6: 006So00000N2H7ZIAV
A7: Supersedes opportunity | B7: 006So00000CNv9xIAD
A8: Quote type | B8: Auto-renewal
A9: Term start | B9: 45803
A10: Term end | B10: 46168
A11: Term (months) | B11: 12
A12: Currency | B12: USD
A13: Rate card | B13: Rate Card D USD Default Pricing
A14: Bill frequency | B14: Monthly
A15: Minimum prepayment (USD) | B15: 15000
A16: CSM fee commitment (USD) | B16: 0
A17: Quote total (USD) | B17: =$B$15+$B$16 -> 15000
A19: Price schedule
A20: Line | B20: Accounting product (m3ter) | C20: Product | D20: m3ter meter | E20: Country | F20: Price held on | G20: Rate card price (USD) | H20: Discount | I20: Net price (USD) | J20: Jan 2026 volume (checks) | K20: Jan 2026 value (USD) | L20: Illustrative annual volume (checks) | M20: Illustrative annual value (USD)
A21: A-01 | B21: CPQ_ID_1235 | C21: Document Check - USA | D21: document_report_standard_hybrid | E21: USA | F21: Plan | G21: =INDEX('Rate card D USD'!$E$5:$E$39,MATCH($D21,'Rate card D USD'!$C$5:$C$39,0)) -> 1.59 | H21: =IF(G21=0,0,1-I21/G21) -> 0.74842767 | I21: 0.4 | J21: =SUMIFS('January 2026 bill'!$K$28:$K$54,'January 2026 bill'!$O$28:$O$54,$A21) -> 15767 | K21: =J21*I21 -> 6306.8 | L21: =IF(OR(I21=0,$K$33=0),0,$B$15*K21/$K$33/I21) -> 17901.368 | M21: =L21*I21 -> 7160.5473
A22: A-02 | B22: CPQ_ID_1236 | C22: Document Check - ANY | D22: document_report_standard_hybrid | E22: ANY (all other) | F22: Plan | G22: =INDEX('Rate card D USD'!$E$5:$E$39,MATCH($D22,'Rate card D USD'!$C$5:$C$39,0)) -> 1.59 | H22: =IF(G22=0,0,1-I22/G22) -> 0.57232704 | I22: 0.68 | J22: =SUMIFS('January 2026 bill'!$K$28:$K$54,'January 2026 bill'!$O$28:$O$54,$A22) -> 3939 | K22: =J22*I22 -> 2678.52 | L22: =IF(OR(I22=0,$K$33=0),0,$B$15*K22/$K$33/I22) -> 4472.2198 | M22: =L22*I22 -> 3041.1095
A23: A-03 | B23: document_report_standard_auto | C23: Document Check - Flash | D23: document_report_standard_auto | E23: All | F23: Rate card | G23: =INDEX('Rate card D USD'!$E$5:$E$39,MATCH($D23,'Rate card D USD'!$C$5:$C$39,0)) -> 0.54 | H23: =IF(G23=0,0,1-I23/G23) -> 0 | I23: =G23 -> 0.54 | J23: =SUMIFS('January 2026 bill'!$K$28:$K$54,'January 2026 bill'!$O$28:$O$54,$A23) -> 19 | K23: =J23*I23 -> 10.26 | L23: =IF(OR(I23=0,$K$33=0),0,$B$15*K23/$K$33/I23) -> 21.572017 | M23: =L23*I23 -> 11.648889
A24: A-04 | B24: document_report_standard_manual | C24: Document Check - Sherlock | D24: document_report_standard_manual | E24: All | F24: Rate card | G24: =INDEX('Rate card D USD'!$E$5:$E$39,MATCH($D24,'Rate card D USD'!$C$5:$C$39,0)) -> 2.78 | H24: =IF(G24=0,0,1-I24/G24) -> 0 | I24: =G24 -> 2.78 | J24: =SUMIFS('January 2026 bill'!$K$28:$K$54,'January 2026 bill'!$O$28:$O$54,$A24) -> 1 | K24: =J24*I24 -> 2.78 | L24: =IF(OR(I24=0,$K$33=0),0,$B$15*K24/$K$33/I24) -> 1.1353693 | M24: =L24*I24 -> 3.1563267
A25: A-05 | B25: facial_similarity_report_standard | C25: Facial Similarity Check - Selfie Hybrid | D25: facial_similarity_report_standard | E25: All | F25: Plan | G25: =INDEX('Rate card D USD'!$E$5:$E$39,MATCH($D25,'Rate card D USD'!$C$5:$C$39,0)) -> 0.95 | H25: =IF(G25=0,0,1-I25/G25) -> 0.73684211 | I25: 0.25 | J25: =SUMIFS('January 2026 bill'!$K$28:$K$54,'January 2026 bill'!$O$28:$O$54,$A25) -> 14278 | K25: =J25*I25 -> 3569.5 | L25: =IF(OR(I25=0,$K$33=0),0,$B$15*K25/$K$33/I25) -> 16210.803 | M25: =L25*I25 -> 4052.7008
A26: A-06 | B26: facial_similarity_report_photo_fully_auto | C26: Facial Similarity Check - Selfie Auto | D26: facial_similarity_report_photo_fully_auto | E26: All | F26: Plan | G26: =INDEX('Rate card D USD'!$E$5:$E$39,MATCH($D26,'Rate card D USD'!$C$5:$C$39,0)) -> 0.77 | H26: =IF(G26=0,0,1-I26/G26) -> 0.67532468 | I26: 0.25 | J26: =SUMIFS('January 2026 bill'!$K$28:$K$54,'January 2026 bill'!$O$28:$O$54,$A26) -> 0 | K26: =J26*I26 -> 0 | L26: =IF(OR(I26=0,$K$33=0),0,$B$15*K26/$K$33/I26) -> 0 | M26: =L26*I26 -> 0
A27: A-07 | B27: facial_similarity_report_motion | C27: Motion PLG | D27: facial_similarity_report_motion | E27: All | F27: Plan | G27: =INDEX('Rate card D USD'!$E$5:$E$39,MATCH($D27,'Rate card D USD'!$C$5:$C$39,0)) -> 1.21 | H27: =IF(G27=0,0,1-I27/G27) -> 0.75206612 | I27: 0.3 | J27: =SUMIFS('January 2026 bill'!$K$28:$K$54,'January 2026 bill'!$O$28:$O$54,$A27) -> 2119 | K27: =J27*I27 -> 635.7 | L27: =IF(OR(I27=0,$K$33=0),0,$B$15*K27/$K$33/I27) -> 2405.8476 | M27: =L27*I27 -> 721.75428
A28: A-08 | B28: proof_of_address_report_standard | C28: Proof of Address | D28: proof_of_address_report_standard | E28: All | F28: Plan | G28: =INDEX('Rate card D USD'!$E$5:$E$39,MATCH($D28,'Rate card D USD'!$C$5:$C$39,0)) -> 2.36 | H28: =IF(G28=0,0,1-I28/G28) -> 0.3220339 | I28: 1.6 | J28: =SUMIFS('January 2026 bill'!$K$28:$K$54,'January 2026 bill'!$O$28:$O$54,$A28) -> 5 | K28: =J28*I28 -> 8 | L28: =IF(OR(I28=0,$K$33=0),0,$B$15*K28/$K$33/I28) -> 5.6768466 | M28: =L28*I28 -> 9.0829546
A29: A-09 | B29: known_faces_report_standard | C29: Facial Similarity Check Upgrade - Known Faces | D29: known_faces_report_standard | E29: All | F29: Plan | G29: =INDEX('Rate card D USD'!$E$5:$E$39,MATCH($D29,'Rate card D USD'!$C$5:$C$39,0)) -> 0 | H29: =IF(G29=0,0,1-I29/G29) -> 0 | I29: 0.12 | J29: =SUMIFS('January 2026 bill'!$K$28:$K$54,'January 2026 bill'!$O$28:$O$54,$A29) -> 0 | K29: =J29*I29 -> 0 | L29: =IF(OR(I29=0,$K$33=0),0,$B$15*K29/$K$33/I29) -> 0 | M29: =L29*I29 -> 0
A30: A-10 | B30: repeat_attempts_report_standard | C30: Repeat Attempts | D30: repeat_attempts_report_standard | E30: All | F30: Rate card | G30: =INDEX('Rate card D USD'!$E$5:$E$39,MATCH($D30,'Rate card D USD'!$C$5:$C$39,0)) -> 0 | H30: =IF(G30=0,0,1-I30/G30) -> 0 | I30: =G30 -> 0 | J30: =SUMIFS('January 2026 bill'!$K$28:$K$54,'January 2026 bill'!$O$28:$O$54,$A30) -> 8760 | K30: =J30*I30 -> 0 | L30: =IF(OR(I30=0,$K$33=0),0,$B$15*K30/$K$33/I30) -> 0 | M30: =L30*I30 -> 0
A31: A-11 | B31: applicant_fraud_report_standard | C31: Device Intelligence - Standard | D31: applicant_fraud_report_standard | E31: All | F31: Rate card | G31: =INDEX('Rate card D USD'!$E$5:$E$39,MATCH($D31,'Rate card D USD'!$C$5:$C$39,0)) -> 0 | H31: =IF(G31=0,0,1-I31/G31) -> 0 | I31: =G31 -> 0 | J31: =SUMIFS('January 2026 bill'!$K$28:$K$54,'January 2026 bill'!$O$28:$O$54,$A31) -> 9148 | K31: =J31*I31 -> 0 | L31: =IF(OR(I31=0,$K$33=0),0,$B$15*K31/$K$33/I31) -> 0 | M31: =L31*I31 -> 0
A32: A-12 | B32: autofill | C32: OCR Autofill | D32: autofill | E32: All | F32: Rate card | G32: =INDEX('Rate card D USD'!$E$5:$E$39,MATCH($D32,'Rate card D USD'!$C$5:$C$39,0)) -> 0 | H32: =IF(G32=0,0,1-I32/G32) -> 0 | I32: =G32 -> 0 | J32: =SUMIFS('January 2026 bill'!$K$28:$K$54,'January 2026 bill'!$O$28:$O$54,$A32) -> 32568 | K32: =J32*I32 -> 0 | L32: =IF(OR(I32=0,$K$33=0),0,$B$15*K32/$K$33/I32) -> 0 | M32: =L32*I32 -> 0
A33: Total | K33: =SUM(K21:K32) -> 13211.56 | M33: =SUM(M21:M32) -> 15000
A34: Illustrative annual value less minimum prepayment (USD) | M34: =ROUND(M33-$B$15,2) -> 0
A35: January 2026 usage value times 12 (USD) | K35: =K33*12 -> 158538.72
A36: Minimum prepayment as months of January 2026 usage | K36: =IF(K33=0,0,$B$15/K33) -> 1.1353693
A38: Notes
A39: Price held on: Plan means the price is set on this customer's m3ter plan. Rate card means the plan has no price for the item, so m3ter bills it at the Rate Card D USD price.
A40: Rate card lines are on the quote because they had usage in January 2026. Every other rate card item bills at its rate card price in the same way (see the Rate card D USD tab).
A41: Document Check - Boost is the only product priced by country: USA, and ANY for every other country. Each is a segment price on the country field of an aggregation created for this opportunity over the Boost meter.
A42: Document Check - Flash and Document Check - Sherlock have no negotiated price. They bill at the rate card price, so the discount is zero.
...

Sheet January 2026 bill
A1: January 2026 bill recomputed from quote prices
A2: All 27 line items on the m3ter bill, in bill order, with billed quantities priced at the net prices on the quote tab. Blue: values held in m3ter. Black: formulas. Green: formulas reading another tab.
A3: Source: m3ter data in local Postgres (customerdb, schema entrust), queried by Claude on 7 Oct 2026. The queries are on the Data Sources tab. The bill total is the sum of the line items, because the billTotal column in customerdb is rounded to whole dollars.
C4: Bill summary | E4: Line type summed
C5: Customer | D5: First Mile Group, Inc. d/b/a Alloy
C6: m3ter bill id | D6: 06c06bb9-0775-4d57-b2a0-3a2b7129ea3b
C7: Bill period | D7: 1 Jan 2026 to 1 Feb 2026
C8: Status | D8: APPROVED
C9: Bill date | D9: 46054
C10: Due date | D10: 46068
C11: Last calculated | D11: 46121
C12: Line items | D12: =COUNTA($A$28:$A$54) -> 27
C13: Lines with usage | D13: =COUNTIF($K$28:$K$54,">0") -> 11
C14: Lines with a charge | D14: =COUNTIF($M$28:$M$54,"<>0") -> 7
C15: Lines priced on the plan | D15: =COUNTIF($N$28:$N$54,"Plan") -> 8
C16: Lines priced on the rate card | D16: =COUNTIF($N$28:$N$54,"Rate card") -> 19
C17: Usage at quote prices (USD) | D17: =SUMIFS($Q$28:$Q$54,$B$28:$B$54,$E17) -> 13211.56 | E17: USAGE
C18: Billed usage (USD) | D18: =SUMIFS($M$28:$M$54,$B$28:$B$54,$E18) -> 13211.56 | E18: USAGE
C19: Prepayment drawn down (USD) | D19: =SUMIFS($M$28:$M$54,$B$28:$B$54,$E19) -> 0 | E19: BALANCE_CONSUMED
C20: Bill total recomputed (USD) | D20: =D17+D19 -> 13211.56
C21: Bill total from line items (USD) | D21: =SUM($M$28:$M$54) -> 13211.56
C22: Difference (USD) | D22: =ROUND(D20-D21,2) -> 0
C23: billTotal in customerdb (whole USD) | D23: 13212
C24: Recomputed total rounded, less billTotal (USD) | D24: =ROUND(D20,0)-D23 -> 0
A26: Bill lines
A27: Line | B27: Line type | C27: Accounting product | D27: Accounting product name | E27: Line description on bill | F27: m3ter aggregation | G27: m3ter meter | H27: Country segment | I27: Service period start | J27: Service period end | K27: Quantity | L27: Billed unit price (USD) | M27: Billed subtotal (USD) | N27: Price held on | O27: Quote line | P27: Quote net price (USD) | Q27: Recomputed subtotal (USD) | R27: Difference (USD) | S27: Note
A28: 1 | B28: USAGE | C28: eid_spid_full | D28: eID, Italy - SPID Full | E28: eID, Italy - SPID Full | F28: eid_spid_full_count | G28: eid_spid_full | I28: 46023 | J28: 46054 | K28: 0 | L28: 0 | M28: 0 | N28: Rate card | P28: =INDEX('Rate card D USD'!$E$5:$E$39,MATCH($F28,'Rate card D USD'!$A$5:$A$39,0)) -> 10.29 | Q28: =ROUND(K28*P28,2) -> 0 | R28: =Q28-M28 -> 0 | S28: Rate card item, no usage in January
A29: 2 | B29: USAGE | C29: repeat_attempts_report_standard | D29: Repeat Attempts | E29: Repeat Attempts | F29: repeat_attempts_report_standard_count | G29: repeat_attempts_report_standard | I29: 46023 | J29: 46054 | K29: 8760 | L29: 0 | M29: 0 | N29: Rate card | O29: A-10 | P29: =INDEX('Alloy quote'!$I$21:$I$32,MATCH($O29,'Alloy quote'!$A$21:$A$32,0)) -> 0 | Q29: =ROUND(K29*P29,2) -> 0 | R29: =Q29-M29 -> 0
A30: 3 | B30: USAGE | C30: facial_similarity_report_standard | D30: Facial Similarity Check - Selfie Hybrid | E30: Facial Similarity Check - Selfie Hybrid | F30: facial_similarity_report_standard_count | G30: facial_similarity_report_standard | I30: 46023 | J30: 46054 | K30: 14278 | L30: 0.25 | M30: 3569.5 | N30: Plan | O30: A-05 | P30: =INDEX('Alloy quote'!$I$21:$I$32,MATCH($O30,'Alloy quote'!$A$21:$A$32,0)) -> 0.25 | Q30: =ROUND(K30*P30,2) -> 3569.5 | R30: =Q30-M30 -> 0
A31: 4 | B31: USAGE | C31: autofill | D31: OCR Autofill | E31: OCR Autofill | F31: autofill_count | G31: autofill | I31: 46023 | J31: 46054 | K31: 32568 | L31: 0 | M31: 0 | N31: Rate card | O31: A-12 | P31: =INDEX('Alloy quote'!$I$21:$I$32,MATCH($O31,'Alloy quote'!$A$21:$A$32,0)) -> 0 | Q31: =ROUND(K31*P31,2) -> 0 | R31: =Q31-M31 -> 0
A32: 5 | B32: USAGE | C32: watchlist_report_full | D32: Watchlist - Standard (Full) | E32: Watchlist - Standard (Full) | F32: watchlist_report_full_count | G32: watchlist_report_full | I32: 46023 | J32: 46054 | K32: 0 | L32: 0 | M32: 0 | N32: Rate card | P32: =INDEX('Rate card D USD'!$E$5:$E$39,MATCH($F32,'Rate card D USD'!$A$5:$A$39,0)) -> 0.42 | Q32: =ROUND(K32*P32,2) -> 0 | R32: =Q32-M32 -> 0 | S32: Rate card item, no usage in January
A33: 6 | B33: USAGE | C33: document_report_standard_hybrid | D33: Document Check - Boost | E33: Document Check - Boost | F33: document_report_standard_hybrid_count | G33: document_report_standard_hybrid | I33: 46023 | J33: 46054 | K33: 19706 | L33: 0 | M33: 0 | N33: Plan | P33: 0 | Q33: =ROUND(K33*P33,2) -> 0 | R33: =Q33-M33 -> 0 | S33: m3ter total-count line at 0.00, not a quote line. Quantity is the USA and ANY lines added together.
A34: 7 | B34: USAGE | C34: us_driving_licence_report_standard | D34: AAMVA Check | E34: AAMVA Check | F34: us_driving_licence_report_standard_count | G34: us_driving_licence_report_standard | I34: 46023 | J34: 46054 | K34: 0 | L34: 0 | M34: 0 | N34: Rate card | P34: =INDEX('Rate card D USD'!$E$5:$E$39,MATCH($F34,'Rate card D USD'!$A$5:$A$39,0)) -> 1.98 | Q34: =ROUND(K34*P34,2) -> 0 | R34: =Q34-M34 -> 0 | S34: Rate card item, no usage in January
A35: 8 | B35: USAGE | C35: identity_report_standard | D35: ID Record | E35: ID Record | F35: identity_report_standard_count | G35: identity_report_standard | I35: 46023 | J35: 46054 | K35: 0 | L35: 0 | M35: 0 | N35: Rate card | P35: =INDEX('Rate card D USD'!$E$5:$E$39,MATCH($F35,'Rate card D USD'!$A$5:$A$39,0)) -> 1.38 | Q35: =ROUND(K35*P35,2) -> 0 | R35: =Q35-M35 -> 0 | S35: Rate card item, no usage in January
A36: 9 | B36: USAGE | C36: watchlist_report_kyc | D36: Watchlist - Enhanced (KYC) | E36: Watchlist - Enhanced (KYC) | F36: watchlist_report_kyc_count | G36: watchlist_report_kyc | I36: 46023 | J36: 46054 | K36: 0 | L36: 0 | M36: 0 | N36: Rate card | P36: =INDEX('Rate card D USD'!$E$5:$E$39,MATCH($F36,'Rate card D USD'!$A$5:$A$39,0)) -> 0.49 | Q36: =ROUND(K36*P36,2) -> 0 | R36: =Q36-M36 -> 0 | S36: Rate card item, no usage in January
A37: 10 | B37: USAGE | C37: india_pan_report_standard | D37: India Tax ID | E37: India Tax ID | F37: india_pan_report_standard_count | G37: india_pan_report_standard | I37: 46023 | J37: 46054 | K37: 0 | L37: 0 | M37: 0 | N37: Rate card | P37: =INDEX('Rate card D USD'!$E$5:$E$39,MATCH($F37,'Rate card D USD'!$A$5:$A$39,0)) -> 0.25 | Q37: =ROUND(K37*P37,2) -> 0 | R37: =Q37-M37 -> 0 | S37: Rate card item, no usage in January
A38: 11 | B38: USAGE | C38: facial_similarity_report_video | D38: Facial Similarity Check - Video | E38: Facial Similarity Check - Video | F38: facial_similarity_report_video_count | G38: facial_similarity_report_video | I38: 46023 | J38: 46054 | K38: 0 | L38: 0 | M38: 0 | N38: Rate card | P38: =INDEX('Rate card D USD'!$E$5:$E$39,MATCH($F38,'Rate card D USD'!$A$5:$A$39,0)) -> 1.36 | Q38: =ROUND(K38*P38,2) -> 0 | R38: =Q38-M38 -> 0 | S38: Rate card item, no usage in January
A39: 12 | B39: USAGE | C39: document_report_standard_manual | D39: Document Check - Sherlock | E39: Document Check - Sherlock | F39: document_report_standard_manual_count | G39: document_report_standard_manual | I39: 46023 | J39: 46054 | K39: 1 | L39: 2.78 | M39: 2.78 | N39: Rate card | O39: A-04 | P39: =INDEX('Alloy quote'!$I$21:$I$32,MATCH($O39,'Alloy quote'!$A$21:$A$32,0)) -> 2.78 | Q39: =ROUND(K39*P39,2) -> 2.78 | R39: =Q39-M39 -> 0
A40: 13 | B40: USAGE | C40: eid_spid_basic | D40: eID, Italy - SPID Basic | E40: eID, Italy - SPID Basic | F40: eid_spid_basic_count | G40: eid_spid_basic | I40: 46023 | J40: 46054 | K40: 0 | L40: 0 | M40: 0 | N40: Rate card | P40: =INDEX('Rate card D USD'!$E$5:$E$39,MATCH($F40,'Rate card D USD'!$A$5:$A$39,0)) -> 5.97 | Q40: =ROUND(K40*P40,2) -> 0 | R40: =Q40-M40 -> 0 | S40: Rate card item, no usage in January
A41: 14 | B41: USAGE | C41: document_report_video | D41: Document Check Video - Boost | E41: Document Check Video - Boost | F41: document_report_video_count | G41: document_report_video | I41: 46023 | J41: 46054 | K41: 0 | L41: 0 | M41: 0 | N41: Rate card | P41: =INDEX('Rate card D USD'!$E$5:$E$39,MATCH($F41,'Rate card D USD'!$A$5:$A$39,0)) -> 2.05 | Q41: =ROUND(K41*P41,2) -> 0 | R41: =Q41-M41 -> 0 | S41: Rate card item, no usage in January
...

Sheet Rate card D USD
A1: Rate Card D USD Default Pricing: the plan template behind the customer's plan
A2: All 35 prices on the m3ter plan template rate_card_d_usd_default_pricing. Each has one price band, starts on 1900-01-01 and has no end date. Blue: values held in m3ter. Green: formulas reading another tab.
A3: Source: m3ter data in local Postgres (customerdb, schema entrust), queried by Claude on 7 Oct 2026. The queries are on the Data Sources tab.
A4: m3ter aggregation | B4: Product | C4: m3ter meter | D4: Segment | E4: Rate card price (USD) | F4: Lines on January 2026 bill
A5: advanced_electronic_signature_count | B5: Signhost | C5: advanced_electronic_signature | E5: 1.33 | F5: =COUNTIF('January 2026 bill'!$F$28:$F$54,$A5) -> 0
A6: applicant_fraud_report_standard_count | B6: Device Intelligence - Standard | C6: applicant_fraud_report_standard | E6: 0 | F6: =COUNTIF('January 2026 bill'!$F$28:$F$54,$A6) -> 1
A7: autofill_count | B7: OCR Autofill | C7: autofill | E7: 0 | F7: =COUNTIF('January 2026 bill'!$F$28:$F$54,$A7) -> 1
A8: document_report_driver_verification_count | B8: Document Check - Driver Verification | C8: document_report_driver_verification | E8: 1.59 | F8: =COUNTIF('January 2026 bill'!$F$28:$F$54,$A8) -> 0
A9: document_report_standard_auto_count | B9: Document Check - Flash | C9: document_report_standard_auto | E9: 0.54 | F9: =COUNTIF('January 2026 bill'!$F$28:$F$54,$A9) -> 1
A10: document_report_standard_hybrid_count | B10: Document Check - Boost | C10: document_report_standard_hybrid | E10: 1.59 | F10: =COUNTIF('January 2026 bill'!$F$28:$F$54,$A10) -> 1
A11: document_report_standard_manual_count | B11: Document Check - Sherlock | C11: document_report_standard_manual | E11: 2.78 | F11: =COUNTIF('January 2026 bill'!$F$28:$F$54,$A11) -> 1
A12: document_report_video_ETSI_Certified_IDV_count | B12: Document Check Video - Boost - ETSI Certified IDV | C12: document_report_video_ETSI_Certified_IDV | D12: is_retry:false | E12: 3.72 | F12: =COUNTIF('January 2026 bill'!$F$28:$F$54,$A12) -> 0
A13: document_report_video_ETSI_Certified_IDV_count | B13: Document Check Video - Boost - ETSI Certified IDV | C13: document_report_video_ETSI_Certified_IDV | D13: is_retry:true | E13: 3.72 | F13: =COUNTIF('January 2026 bill'!$F$28:$F$54,$A13) -> 0
A14: document_report_video_ETSI_Certified_IDV_with_QES_and_OTP_count | B14: Document Check Video | C14: document_report_video_ETSI_Certified_IDV_with_QES_and_OTP | D14: is_retry:false | E14: 4.03 | F14: =COUNTIF('January 2026 bill'!$F$28:$F$54,$A14) -> 0
A15: document_report_video_ETSI_Certified_IDV_with_QES_and_OTP_count | B15: Document Check Video | C15: document_report_video_ETSI_Certified_IDV_with_QES_and_OTP | D15: is_retry:true | E15: 4.03 | F15: =COUNTIF('January 2026 bill'!$F$28:$F$54,$A15) -> 0
A16: document_report_video_count | B16: Document Check Video - Boost | C16: document_report_video | E16: 2.05 | F16: =COUNTIF('January 2026 bill'!$F$28:$F$54,$A16) -> 1
A17: eid_spid_basic_count | B17: eID, Italy - SPID Basic | C17: eid_spid_basic | E17: 5.97 | F17: =COUNTIF('January 2026 bill'!$F$28:$F$54,$A17) -> 1
A18: eid_spid_full_count | B18: eID, Italy - SPID Full | C18: eid_spid_full | E18: 10.29 | F18: =COUNTIF('January 2026 bill'!$F$28:$F$54,$A18) -> 1
A19: facial_similarity_report_motion_count | B19: Motion PLG | C19: facial_similarity_report_motion | E19: 1.21 | F19: =COUNTIF('January 2026 bill'!$F$28:$F$54,$A19) -> 1
A20: facial_similarity_report_photo_fully_auto_count | B20: Facial Similarity Check - Selfie Auto | C20: facial_similarity_report_photo_fully_auto | E20: 0.77 | F20: =COUNTIF('January 2026 bill'!$F$28:$F$54,$A20) -> 1
A21: facial_similarity_report_standard_count | B21: Facial Similarity Check - Selfie Hybrid | C21: facial_similarity_report_standard | E21: 0.95 | F21: =COUNTIF('January 2026 bill'!$F$28:$F$54,$A21) -> 1
A22: facial_similarity_report_video_count | B22: Facial Similarity Check - Video | C22: facial_similarity_report_video | E22: 1.36 | F22: =COUNTIF('January 2026 bill'!$F$28:$F$54,$A22) -> 1
A23: identity_report_standard_count | B23: ID Record | C23: identity_report_standard | E23: 1.38 | F23: =COUNTIF('January 2026 bill'!$F$28:$F$54,$A23) -> 1
A24: india_pan_report_standard_count | B24: India Tax ID | C24: india_pan_report_standard | E24: 0.25 | F24: =COUNTIF('January 2026 bill'!$F$28:$F$54,$A24) -> 1
A25: known_faces_report_standard_count | B25: Facial Similarity Check Upgrade - Known Faces | C25: known_faces_report_standard | E25: 0 | F25: =COUNTIF('January 2026 bill'!$F$28:$F$54,$A25) -> 1
A26: mastercard_identity_account_opening_amer_count | B26: Mastercard Identity | C26: mastercard_identity_account_opening_amer | E26: 0.3 | F26: =COUNTIF('January 2026 bill'!$F$28:$F$54,$A26) -> 0
A27: mastercard_identity_account_opening_emea_count | B27: Mastercard Identity | C27: mastercard_identity_account_opening_emea | E27: 0.3 | F27: =COUNTIF('January 2026 bill'!$F$28:$F$54,$A27) -> 0
... A39: watchlist_report_kyc_count | B39: Watchlist - Enhanced (KYC) | C39: watchlist_report_kyc | E39: 0.49 | F39: =COUNTIF('January 2026 bill'!$F$28:$F$54,$A39) -> 1
A41: Notes
A42: The customer's plan (checks_006So00000N2H7ZIAV) is built on this template. It sets 8 prices of its own. Six replace a price here; the other two are the USA and ANY country prices on the opportunity's own Boost aggregation, which is not on the rate card.
A43: 25 of the 33 rate card items appear on the January 2026 bill. With the two country lines that makes the bill's 27 lines.
A44: The two Document Check Video items are priced per is_retry segment, so they take two rows each.

Sheet Data Sources
A1: Written to | B1: Source | C1: Object | D1: Obtained via | E1: Query or request | F1: Parameters | G1: Run at | H1: Requested by | I1: Row count | J1: Changes after retrieval | K1: Notes
A2: 'Alloy quote'!A4:B16 (except B7) | B2: m3ter data in local Postgres (customerdb, schema entrust) | C2: customerdb.entrust.accounts, contracts, accountplans, plans, plantemplates | D2: Read-only SQL through the Postgres MCP server, run by Claude | E2: SELECT a.id AS account_id, a.name AS account, a.code AS account_code, a.currency AS account_currency, c.id AS contract_id, c.code AS contract_code, c."startDate", c."endDate", c."customFields_opportunityId" AS opp, c."customFields_contractLength" AS term_months, c."customFields_nsUsageACV" AS usage_acv, c."customFields_CSMFeeCommitment" AS csm_fee, c."customFields_billingType" AS billing_type, ap."startDate" AS ap_start, ap."endDate" AS ap_end, p.id AS plan_id, p.code AS plan_code, p.name AS plan_name, pt.code AS template_code, pt.name AS rate_card, pt."billFrequency" AS bill_frequency, pt.currency AS template_currency FROM entrust.accounts a LEFT JOIN entrust.contracts c ON c."accountId" = a.id LEFT JOIN entrust.accountplans ap ON ap."accountId" = a.id LEFT JOIN entrust.plans p ON p.id = ap."planId" LEFT JOIN entrust.plantemplates pt ON pt.id = p."planTemplateId" WHERE a.code = '00124000018txRVAAY' ORDER BY ap."startDate" | F2: None | G2: 2026-10-07, 19:30 to 19:40 IST (UTC+01:00) | H2: John Griffin | I2: 1 | J2: One row laid out as label and value. Quote type taken from the plan name. Empty CSM fee shown as 0. Minimum prepayment is usage_acv.
A3: 'Alloy quote'!B7 | B3: m3ter data in local Postgres (customerdb, schema entrust) | C3: customerdb.entrust.plans | D3: Read-only SQL through the Postgres MCP server, run by Claude | E3: SELECT row_to_json(t)::text FROM (SELECT * FROM entrust.plans WHERE id = '5c481fcd-b0aa-4fe5-aa37-1806ef04c488') t | F3: None | G3: 2026-10-07, 19:30 to 19:40 IST (UTC+01:00) | H3: John Griffin | I3: 1 | J3: customFields_superseededOppId only.
A4: 'Alloy quote'!A20:F32 and I21:I32 (plan lines) | B4: m3ter data in local Postgres (customerdb, schema entrust) | C4: customerdb.entrust.pricings, aggregations, meters, products | D4: Read-only SQL through the Postgres MCP server, run by Claude | E4: SELECT pr.id, ag.code AS agg_code, ag.name AS agg_name, ag."segmentedFields"::text AS seg_fields, m.code AS meter_code, pr."segmentString" AS segment, pr.description, ap2.code AS acct_product_code, ap2.name AS acct_product_name, pr."pricingBands"::text AS bands, pr."startDate", pr."endDate" FROM entrust.pricings pr LEFT JOIN entrust.aggregations ag ON ag.id = pr."aggregationId" LEFT JOIN entrust.meters m ON m.id = ag."meterId" LEFT JOIN entrust.products ap2 ON ap2.id = pr."accountingProductId" WHERE pr."planId" = '5c481fcd-b0aa-4fe5-aa37-1806ef04c488' ORDER BY m.code, ag.code, pr."segmentString", pr."startDate" | F4: None | G4: 2026-10-07, 19:30 to 19:40 IST (UTC+01:00) | H4: John Griffin | I4: 8 | J4: Seven of the eight plan prices became quote lines; the 0.00 price on the plain Boost count is not a quote line. Line ids added. Rate card lines (A-03, A-04, A-10, A-11, A-12) added from the bill because they had January usage.
A5: 'Rate card D USD'!A4:E39 | B5: m3ter data in local Postgres (customerdb, schema entrust) | C5: customerdb.entrust.pricings, aggregations, meters (plan template rate_card_d_usd_default_pricing) | D5: Read-only SQL through the Postgres MCP server, run by Claude | E5: SELECT ag.code AS agg, ag.name, m.code AS meter, pr."segmentString" AS seg, LEFT(pr."startDate",10) AS s, LEFT(pr."endDate",10) AS e, (pr."pricingBands"->0->>'unitPrice') AS price, json_array_length(pr."pricingBands") AS bands FROM entrust.pricings pr JOIN entrust.aggregations ag ON ag.id = pr."aggregationId" LEFT JOIN entrust.meters m ON m.id = ag."meterId" WHERE pr."planTemplateId" = '6a7362d2-acff-49cc-9039-c9af9ed9ca6a' ORDER BY ag.code, pr."startDate" | F5: None | G5: 2026-10-07, 19:30 to 19:40 IST (UTC+01:00) | H5: John Griffin | I5: 35 | J5: None. Rows were loaded from the config JSON built for the structure chart, whose rate card section matches this query (md5 of all 35 rows). | K5: All open-ended, one price band each.
A6: 'January 2026 bill'!A27:N54 | B6: m3ter data in local Postgres (customerdb, schema entrust) | C6: customerdb.entrust.bills (lineItems), aggregations, meters | D6: Read-only SQL through the Postgres MCP server, run by Claude | E6: SELECT (li->>'sequenceNumber')::int AS seq, li->>'lineItemType' AS type, li->>'accountingProductCode' AS acct_product_code, li->>'accountingProductName' AS acct_product_name, li->>'description' AS description, ag.code AS agg_code, m.code AS meter_code, li->>'segment' AS segment, (li->>'quantity')::numeric AS qty, (li->>'averageUnitPrice')::numeric AS avg_price, (li->>'subtotal')::numeric AS subtotal, LEFT(li->>'servicePeriodStartDate',10) AS sp_start, LEFT(li->>'servicePeriodEndDate',10) AS sp_end, li->>'pricingId' AS pricing_id FROM entrust.bills b CROSS JOIN LATERAL json_array_elements(b."lineItems") li LEFT JOIN entrust.aggregations ag ON ag.id = li->>'aggregationId' LEFT JOIN entrust.meters m ON m.id = li->>'meterId' WHERE b.id = '06c06bb9-0775-4d57-b2a0-3a2b7129ea3b' ORDER BY 1 | F6: None | G6: 2026-10-07, 19:30 to 19:40 IST (UTC+01:00) | H6: John Griffin | I6: 27 | J6: Price held on derived from pricing_id (the plan's 8 pricing ids against the rest). Empty country segment on line 25 shown as ANY. Quote line and Note columns added.
A7: 'January 2026 bill'!D5:D11 and D23 | B7: m3ter data in local Postgres (customerdb, schema entrust) | C7: customerdb.entrust.bills | D7: Read-only SQL through the Postgres MCP server, run by Claude | E7: SELECT b.id, b."startDate", b."endDate", b."billDate", b."dueDate", b.status, b.currency, b."billTotal", b."lastCalculatedDate", json_array_length(b."lineItems") AS lines, (SELECT ROUND(SUM((li->>'subtotal')::numeric),2) FROM json_array_elements(b."lineItems") li) AS net, (SELECT string_agg(DISTINCT li->>'lineItemType', ',') FROM json_array_elements(b."lineItems") li) AS types FROM entrust.bills b WHERE b."accountCode" = '00124000018txRVAAY' ORDER BY b."startDate" | F7: None | G7: 2026-10-07, 19:30 to 19:40 IST (UTC+01:00) | H7: John Griffin | I7: 3 | J7: January 2026 row used. The other two rows (November and December 2025) were used only to confirm there is no drawdown line. | K7: billTotal is stored rounded to whole dollars (13,212).
A8: Notes on prepayment | B8: m3ter data in local Postgres (customerdb, schema entrust) | C8: customerdb.entrust.balances | D8: Read-only SQL through the Postgres MCP server, run by Claude | E8: SELECT id, name, code, amount, currency, "startDate", "endDate", "rolloverAmount", "lineItemTypes"::text, "balanceDrawDownDescription", "contractId" FROM entrust.balances WHERE "accountId" = 'fc1314aa-7a85-4770-86d6-40659e2ac785' ORDER BY "startDate" | F8: None | G8: 2026-10-07, 19:30 to 19:40 IST (UTC+01:00) | H8: John Griffin | I8: 1 | J8: Not written to a cell. Balance amount is 0.00 for 26 May 2025 to 26 May 2026.
