Workbook

Sheet Signicat quote
A1: Signicat AS: renewal quote, July 2025
A2: Reconstructed from m3ter. Blue: values held in m3ter. Black: formulas. Green: formulas reading the January 2026 bills tab. Yellow: illustrative, not held in m3ter.
A3: Source: m3ter data in local Postgres (customerdb, schema entrust), queried by Claude on 6 Oct 2026. The queries are on the Data Sources tab.
A4: Customer | B4: Signicat AS
A5: m3ter account code | B5: 0012400001GbKtsAAF
A6: Salesforce opportunity | B6: 006So00000KusqKIAR
A7: Quote type | B7: Renewal
A8: Term start | B8: 45839
A9: Term end | B9: 46204
A10: Term (months) | B10: 12
A11: Currency | B11: EUR
A12: Rate card | B12: Rate Card B EUR Default Pricing
A13: Bill frequency | B13: Monthly
A14: Minimum prepayment (EUR) | B14: 201262.83
A15: CSM fee commitment (EUR) | B15: 0
A16: Quote total (EUR) | B16: =B14+B15 -> 201262.83
A18: Price schedule
A19: Line | B19: Accounting product (m3ter) | C19: Product | D19: m3ter meter | E19: Country | F19: Rate card price (EUR) | G19: Discount | H19: Net price (EUR) | I19: Jan 2026 volume (checks) | J19: Jan 2026 value (EUR) | K19: Illustrative annual volume (checks) | L19: Illustrative annual value (EUR)
A20: S-01 | B20: document_report_standard_hybrid | C20: Document Check - Boost | D20: document_report_standard_hybrid | E20: All | F20: 2.28 | G20: =IF(F20=0,0,1-H20/F20) -> 0.6622807 | H20: 0.77 | I20: =SUMIFS('January 2026 bills'!$I$11:$I$50,'January 2026 bills'!$L$11:$L$50,$A20) -> 16739 | J20: =I20*H20 -> 12889.03 | K20: =IF(OR(H20=0,$J$32=0),0,$B$14*J20/$J$32/H20) -> 141862.83 | L20: =K20*H20 -> 109234.38
A21: S-02 | B21: document_report_standard_auto | C21: Document Check - Flash | D21: document_report_standard_auto | E21: All | F21: 0.65 | G21: =IF(F21=0,0,1-H21/F21) -> 0.66153846 | H21: 0.22 | I21: =SUMIFS('January 2026 bills'!$I$11:$I$50,'January 2026 bills'!$L$11:$L$50,$A21) -> 7220 | J21: =I21*H21 -> 1588.4 | K21: =IF(OR(H21=0,$J$32=0),0,$B$14*J21/$J$32/H21) -> 61189.414 | L21: =K21*H21 -> 13461.671
A22: S-03 | B22: document_report_standard_manual | C22: Document Check - Sherlock | D22: document_report_standard_manual | E22: All | F22: 3.02 | G22: =IF(F22=0,0,1-H22/F22) -> 0.74503311 | H22: 0.77 | I22: =SUMIFS('January 2026 bills'!$I$11:$I$50,'January 2026 bills'!$L$11:$L$50,$A22) -> 5673 | J22: =I22*H22 -> 4368.21 | K22: =IF(OR(H22=0,$J$32=0),0,$B$14*J22/$J$32/H22) -> 48078.607 | L22: =K22*H22 -> 37020.528
A23: S-04 | B23: document_report_driver_verification | C23: Document Check - Driver Verification | D23: document_report_driver_verification | E23: All | F23: 2.28 | G23: =IF(F23=0,0,1-H23/F23) -> 0.6622807 | H23: 0.77 | I23: =SUMIFS('January 2026 bills'!$I$11:$I$50,'January 2026 bills'!$L$11:$L$50,$A23) -> 66 | J23: =I23*H23 -> 50.82 | K23: =IF(OR(H23=0,$J$32=0),0,$B$14*J23/$J$32/H23) -> 559.34921 | L23: =K23*H23 -> 430.69889
A24: S-05 | B24: facial_similarity_report_standard | C24: Facial Similarity Check - Selfie Hybrid | D24: facial_similarity_report_standard | E24: All | F24: 1.08 | G24: =IF(F24=0,0,1-H24/F24) -> 0.65740741 | H24: 0.37 | I24: =SUMIFS('January 2026 bills'!$I$11:$I$50,'January 2026 bills'!$L$11:$L$50,$A24) -> 12970 | J24: =I24*H24 -> 4798.9 | K24: =IF(OR(H24=0,$J$32=0),0,$B$14*J24/$J$32/H24) -> 109920.6 | L24: =K24*H24 -> 40670.62
A25: S-06 | B25: facial_similarity_report_video | C25: Facial Similarity Check - Video | D25: facial_similarity_report_video | E25: All | F25: 1.53 | G25: =IF(F25=0,0,1-H25/F25) -> 0.50980392 | H25: 0.75 | I25: =SUMIFS('January 2026 bills'!$I$11:$I$50,'January 2026 bills'!$L$11:$L$50,$A25) -> 70 | J25: =I25*H25 -> 52.5 | K25: =IF(OR(H25=0,$J$32=0),0,$B$14*J25/$J$32/H25) -> 593.24916 | L25: =K25*H25 -> 444.93687
A26: S-07 | B26: facial_similarity_report_motion_ETSI_Certified_IDV_with_QES_and_OTP | C26: Motion (ETSI Certified IDV with QES and OTP) | D26: facial_similarity_report_motion | E26: All | F26: 1.36 | G26: =IF(F26=0,0,1-H26/F26) -> 0.625 | H26: 0.51 | I26: =SUMIFS('January 2026 bills'!$I$11:$I$50,'January 2026 bills'!$L$11:$L$50,$A26) -> 0 | J26: =I26*H26 -> 0 | K26: =IF(OR(H26=0,$J$32=0),0,$B$14*J26/$J$32/H26) -> 0 | L26: =K26*H26 -> 0
A27: S-08 | B27: proof_of_address_report_standard | C27: Proof of Address | D27: proof_of_address_report_standard | E27: All | F27: 2.28 | G27: =IF(F27=0,0,1-H27/F27) -> 0.22807018 | H27: 1.76 | I27: =SUMIFS('January 2026 bills'!$I$11:$I$50,'January 2026 bills'!$L$11:$L$50,$A27) -> 0 | J27: =I27*H27 -> 0 | K27: =IF(OR(H27=0,$J$32=0),0,$B$14*J27/$J$32/H27) -> 0 | L27: =K27*H27 -> 0
A28: S-09 | B28: known_faces_report_standard | C28: Facial Similarity Check Upgrade - Known Faces | D28: known_faces_report_standard | E28: All | F28: 0 | G28: =IF(F28=0,0,1-H28/F28) -> 0 | H28: 0 | I28: =SUMIFS('January 2026 bills'!$I$11:$I$50,'January 2026 bills'!$L$11:$L$50,$A28) -> 2 | J28: =I28*H28 -> 0 | K28: =IF(OR(H28=0,$J$32=0),0,$B$14*J28/$J$32/H28) -> 0 | L28: =K28*H28 -> 0
A29: S-10 | B29: repeat_attempts_report_standard | C29: Repeat Attempts | D29: repeat_attempts_report_standard | E29: All | F29: 0 | G29: =IF(F29=0,0,1-H29/F29) -> 0 | H29: 0 | I29: =SUMIFS('January 2026 bills'!$I$11:$I$50,'January 2026 bills'!$L$11:$L$50,$A29) -> 27232 | J29: =I29*H29 -> 0 | K29: =IF(OR(H29=0,$J$32=0),0,$B$14*J29/$J$32/H29) -> 0 | L29: =K29*H29 -> 0
A30: S-11 | B30: applicant_fraud_report_standard | C30: Device Intelligence - Standard | D30: applicant_fraud_report_standard | E30: All | F30: 0 | G30: =IF(F30=0,0,1-H30/F30) -> 0 | H30: 0 | I30: =SUMIFS('January 2026 bills'!$I$11:$I$50,'January 2026 bills'!$L$11:$L$50,$A30) -> 0 | J30: =I30*H30 -> 0 | K30: =IF(OR(H30=0,$J$32=0),0,$B$14*J30/$J$32/H30) -> 0 | L30: =K30*H30 -> 0
A31: S-12 | B31: autofill | C31: OCR Autofill | D31: autofill | E31: All | F31: 0 | G31: =IF(F31=0,0,1-H31/F31) -> 0 | H31: 0 | I31: =SUMIFS('January 2026 bills'!$I$11:$I$50,'January 2026 bills'!$L$11:$L$50,$A31) -> 0 | J31: =I31*H31 -> 0 | K31: =IF(OR(H31=0,$J$32=0),0,$B$14*J31/$J$32/H31) -> 0 | L31: =K31*H31 -> 0
A32: Total | J32: =SUM(J20:J31) -> 23747.86 | L32: =SUM(L20:L31) -> 201262.83
A33: Illustrative annual value less minimum prepayment (EUR) | L33: =ROUND(L32-B14,2) -> 0
A35: Notes
A36: Illustrative annual volume splits the minimum prepayment across lines in proportion to January 2026 billed value, then divides by net price. The volumes actually quoted are not held in m3ter.
A37: Lines with no January 2026 usage get no illustrative volume.
A38: Lines priced at 0.00 are included at no charge.
A39: Minimum prepayment is the contract's usage ACV (customFields_nsUsageACV). On Wolt's 2026 contract that figure less the January drawdown equals the balance m3ter still holds (700,181.60 - 10,556.65 = 689,624.95).
A40: CSM fee commitment is customFields_CSMFeeCommitment on the contract. Empty is shown as 0.
A41: Document checks are priced by check type only. The meters carry a country field, but this quote does not use it.
A42: m3ter holds no CPQ SKU ids for these lines, so the accounting product is the m3ter product code.

Sheet Wolt quote 2025
A1: Wolt Enterprises Oy: renewal quote, January 2025
A2: Reconstructed from m3ter. Blue: values held in m3ter. Black: formulas. Green: formulas reading the January 2026 bills tab. Yellow: illustrative, not held in m3ter.
A3: Source: m3ter data in local Postgres (customerdb, schema entrust), queried by Claude on 6 Oct 2026. The queries are on the Data Sources tab.
A4: Customer | B4: Wolt Enterprises Oy
A5: m3ter account code | B5: 0012400000bYaokAAC
A6: Salesforce opportunity | B6: 006So00000HLTq3IAH
A7: Quote type | B7: Renewal
A8: Term start | B8: 45685
A9: Term end | B9: 46050
A10: Term (months) | B10: 12
A11: Currency | B11: EUR
A12: Rate card | B12: Rate Card B EUR Default Pricing
A13: Bill frequency | B13: Monthly
A14: Minimum prepayment (EUR) | B14: 390580.54
A15: CSM fee commitment (EUR) | B15: 0
A16: Quote total (EUR) | B16: =B14+B15 -> 390580.54
A18: Price schedule
A19: Line | B19: Accounting product (m3ter) | C19: Product | D19: m3ter meter | E19: Country | F19: Rate card price (EUR) | G19: Discount | H19: Net price (EUR) | I19: Jan 2026 volume (checks) | J19: Jan 2026 value (EUR) | K19: Illustrative annual volume (checks) | L19: Illustrative annual value (EUR)
A20: W25-01 | B20: CPQ_ID_1223 | C20: Document Check - ANY | D20: document_report_standard_hybrid | E20: ANY (all other) | F20: 2.28 | G20: =IF(F20=0,0,1-H20/F20) -> 0.72368421 | H20: 0.63 | I20: =SUMIFS('January 2026 bills'!$I$11:$I$50,'January 2026 bills'!$L$11:$L$50,$A20) -> 34720 | J20: =I20*H20 -> 21873.6 | K20: =IF(OR(H20=0,$J$31=0),0,$B$14*J20/$J$31/H20) -> 202513.14 | L20: =K20*H20 -> 127583.28
A21: W25-02 | B21: CPQ_ID_1221 | C21: Document Check - JPN | D21: document_report_standard_hybrid | E21: JPN | F21: 2.28 | G21: =IF(F21=0,0,1-H21/F21) -> 0.47368421 | H21: 1.2 | I21: =SUMIFS('January 2026 bills'!$I$11:$I$50,'January 2026 bills'!$L$11:$L$50,$A21) -> 1405 | J21: =I21*H21 -> 1686 | K21: =IF(OR(H21=0,$J$31=0),0,$B$14*J21/$J$31/H21) -> 8195.0162 | L21: =K21*H21 -> 9834.0195
A22: W25-03 | B22: CPQ_ID_1222 | C22: Document Check - KAZ,SRB | D22: document_report_standard_hybrid | E22: KAZ; SRB | F22: 2.28 | G22: =IF(F22=0,0,1-H22/F22) -> 0.72368421 | H22: 0.63 | I22: =SUMIFS('January 2026 bills'!$I$11:$I$50,'January 2026 bills'!$L$11:$L$50,$A22) -> 7312 | J22: =I22*H22 -> 4606.56 | K22: =IF(OR(H22=0,$J$31=0),0,$B$14*J22/$J$31/H22) -> 42649.081 | L22: =K22*H22 -> 26868.921
A23: W25-04 | B23: CPQ_ID_1298 | C23: Document Check - ANY | D23: document_report_driver_verification | E23: ANY (all other) | F23: 2.28 | G23: =IF(F23=0,0,1-H23/F23) -> 0.72368421 | H23: 0.63 | I23: =SUMIFS('January 2026 bills'!$I$11:$I$50,'January 2026 bills'!$L$11:$L$50,$A23) -> 3306 | J23: =I23*H23 -> 2082.78 | K23: =IF(OR(H23=0,$J$31=0),0,$B$14*J23/$J$31/H23) -> 19283.077 | L23: =K23*H23 -> 12148.339
A24: W25-05 | B24: CPQ_ID_1297 | C24: Document Check - JPN | D24: document_report_driver_verification | E24: JPN | F24: 2.28 | G24: =IF(F24=0,0,1-H24/F24) -> 0.47368421 | H24: 1.2 | I24: =SUMIFS('January 2026 bills'!$I$11:$I$50,'January 2026 bills'!$L$11:$L$50,$A24) -> 0 | J24: =I24*H24 -> 0 | K24: =IF(OR(H24=0,$J$31=0),0,$B$14*J24/$J$31/H24) -> 0 | L24: =K24*H24 -> 0
A25: W25-06 | B25: facial_similarity_report_standard | C25: Facial Similarity Check - Selfie Hybrid | D25: facial_similarity_report_standard | E25: All | F25: 1.08 | G25: =IF(F25=0,0,1-H25/F25) -> 0.62962963 | H25: 0.4 | I25: =SUMIFS('January 2026 bills'!$I$11:$I$50,'January 2026 bills'!$L$11:$L$50,$A25) -> 45377 | J25: =I25*H25 -> 18150.8 | K25: =IF(OR(H25=0,$J$31=0),0,$B$14*J25/$J$31/H25) -> 264672.78 | L25: =K25*H25 -> 105869.11
A26: W25-07 | B26: facial_similarity_report_motion | C26: Motion PLG | D26: facial_similarity_report_motion | E26: All | F26: 1.36 | G26: =IF(F26=0,0,1-H26/F26) -> 0.70588235 | H26: 0.4 | I26: =SUMIFS('January 2026 bills'!$I$11:$I$50,'January 2026 bills'!$L$11:$L$50,$A26) -> 46409 | J26: =I26*H26 -> 18563.6 | K26: =IF(OR(H26=0,$J$31=0),0,$B$14*J26/$J$31/H26) -> 270692.18 | L26: =K26*H26 -> 108276.87
A27: W25-08 | B27: repeat_attempts_report_standard | C27: Repeat Attempts | D27: repeat_attempts_report_standard | E27: All | F27: 0 | G27: =IF(F27=0,0,1-H27/F27) -> 0 | H27: 0 | I27: =SUMIFS('January 2026 bills'!$I$11:$I$50,'January 2026 bills'!$L$11:$L$50,$A27) -> 41689 | J27: =I27*H27 -> 0 | K27: =IF(OR(H27=0,$J$31=0),0,$B$14*J27/$J$31/H27) -> 0 | L27: =K27*H27 -> 0
A28: W25-09 | B28: applicant_fraud_report_standard | C28: Device Intelligence - Standard | D28: applicant_fraud_report_standard | E28: All | F28: 0 | G28: =IF(F28=0,0,1-H28/F28) -> 0 | H28: 0 | I28: =SUMIFS('January 2026 bills'!$I$11:$I$50,'January 2026 bills'!$L$11:$L$50,$A28) -> 50028 | J28: =I28*H28 -> 0 | K28: =IF(OR(H28=0,$J$31=0),0,$B$14*J28/$J$31/H28) -> 0 | L28: =K28*H28 -> 0
A29: W25-10 | B29: known_faces_report_standard | C29: Facial Similarity Check Upgrade - Known Faces | D29: known_faces_report_standard | E29: All | F29: 0 | G29: =IF(F29=0,0,1-H29/F29) -> 0 | H29: 0 | I29: =SUMIFS('January 2026 bills'!$I$11:$I$50,'January 2026 bills'!$L$11:$L$50,$A29) -> 0 | J29: =I29*H29 -> 0 | K29: =IF(OR(H29=0,$J$31=0),0,$B$14*J29/$J$31/H29) -> 0 | L29: =K29*H29 -> 0
A30: W25-11 | B30: autofill | C30: OCR Autofill | D30: autofill | E30: All | F30: 0 | G30: =IF(F30=0,0,1-H30/F30) -> 0 | H30: 0 | I30: =SUMIFS('January 2026 bills'!$I$11:$I$50,'January 2026 bills'!$L$11:$L$50,$A30) -> 0 | J30: =I30*H30 -> 0 | K30: =IF(OR(H30=0,$J$31=0),0,$B$14*J30/$J$31/H30) -> 0 | L30: =K30*H30 -> 0
A31: Total | J31: =SUM(J20:J30) -> 66963.34 | L31: =SUM(L20:L30) -> 390580.54
A32: Illustrative annual value less minimum prepayment (EUR) | L32: =ROUND(L31-B14,2) -> 0
A34: Notes
A35: Illustrative annual volume splits the minimum prepayment across lines in proportion to January 2026 billed value, then divides by net price. The volumes actually quoted are not held in m3ter.
A36: Lines with no January 2026 usage get no illustrative volume.
A37: Lines priced at 0.00 are included at no charge.
A38: Minimum prepayment is the contract's usage ACV (customFields_nsUsageACV). On Wolt's 2026 contract that figure less the January drawdown equals the balance m3ter still holds (700,181.60 - 10,556.65 = 689,624.95).
A39: CSM fee commitment is customFields_CSMFeeCommitment on the contract. Empty is shown as 0.
A40: Document checks are priced by country. Each country line is a segment of the meter's country field in m3ter.
A41: The Boost meter (document_report_standard_hybrid) and the Driver Verification meter share the same country price points.
A42: KAZ and SRB are one quote line and two segment prices in m3ter.
...

Sheet Wolt quote 2026
A1: Wolt Enterprises Oy: renewal quote, January 2026
A2: Reconstructed from m3ter. Blue: values held in m3ter. Black: formulas. Green: formulas reading the January 2026 bills tab. Yellow: illustrative, not held in m3ter.
A3: Source: m3ter data in local Postgres (customerdb, schema entrust), queried by Claude on 6 Oct 2026. The queries are on the Data Sources tab.
A4: Customer | B4: Wolt Enterprises Oy
A5: m3ter account code | B5: 0012400000bYaokAAC
A6: Salesforce opportunity | B6: 006So00000QJ9IPIA1
A7: Quote type | B7: Renewal
A8: Term start | B8: 46049
A9: Term end | B9: 46414
A10: Term (months) | B10: 12
A11: Currency | B11: EUR
A12: Rate card | B12: Rate Card B EUR Default Pricing
A13: Bill frequency | B13: Monthly
A14: Minimum prepayment (EUR) | B14: 700181.6
A15: CSM fee commitment (EUR) | B15: 9600
A16: Quote total (EUR) | B16: =B14+B15 -> 709781.6
A18: Price schedule
A19: Line | B19: Accounting product (m3ter) | C19: Product | D19: m3ter meter | E19: Country | F19: Rate card price (EUR) | G19: Discount | H19: Net price (EUR) | I19: Jan 2026 volume (checks) | J19: Jan 2026 value (EUR) | K19: Illustrative annual volume (checks) | L19: Illustrative annual value (EUR)
A20: W26-01 | B20: CPQ_ID_1218 | C20: Document Check - ANY | D20: document_report_standard_hybrid | E20: ANY (all other) | F20: 2.28 | G20: =IF(F20=0,0,1-H20/F20) -> 0.76315789 | H20: 0.54 | I20: =SUMIFS('January 2026 bills'!$I$11:$I$50,'January 2026 bills'!$L$11:$L$50,$A20) -> 8027 | J20: =I20*H20 -> 4334.58 | K20: =IF(OR(H20=0,$J$30=0),0,$B$14*J20/$J$30/H20) -> 532399.74 | L20: =K20*H20 -> 287495.86
A21: W26-02 | B21: CPQ_ID_1219 | C21: Document Check - USA | D21: document_report_standard_hybrid | E21: JPN | F21: 2.28 | G21: =IF(F21=0,0,1-H21/F21) -> 0.47368421 | H21: 1.2 | I21: =SUMIFS('January 2026 bills'!$I$11:$I$50,'January 2026 bills'!$L$11:$L$50,$A21) -> 249 | J21: =I21*H21 -> 298.8 | K21: =IF(OR(H21=0,$J$30=0),0,$B$14*J21/$J$30/H21) -> 16515.203 | L21: =K21*H21 -> 19818.244
A22: W26-03 | B22: CPQ_ID_1298 | C22: Document Check - ANY | D22: document_report_driver_verification | E22: ANY (all other) | F22: 2.28 | G22: =IF(F22=0,0,1-H22/F22) -> 0.76315789 | H22: 0.54 | I22: =SUMIFS('January 2026 bills'!$I$11:$I$50,'January 2026 bills'!$L$11:$L$50,$A22) -> 623 | J22: =I22*H22 -> 336.42 | K22: =IF(OR(H22=0,$J$30=0),0,$B$14*J22/$J$30/H22) -> 41321.171 | L22: =K22*H22 -> 22313.432
A23: W26-04 | B23: CPQ_ID_1297 | C23: Document Check - JPN | D23: document_report_driver_verification | E23: JPN | F23: 2.28 | G23: =IF(F23=0,0,1-H23/F23) -> 0.47368421 | H23: 1.2 | I23: =SUMIFS('January 2026 bills'!$I$11:$I$50,'January 2026 bills'!$L$11:$L$50,$A23) -> 0 | J23: =I23*H23 -> 0 | K23: =IF(OR(H23=0,$J$30=0),0,$B$14*J23/$J$30/H23) -> 0 | L23: =K23*H23 -> 0
A24: W26-05 | B24: facial_similarity_report_standard | C24: Facial Similarity Check - Selfie Hybrid | D24: facial_similarity_report_standard | E24: All | F24: 1.08 | G24: =IF(F24=0,0,1-H24/F24) -> 0.73148148 | H24: 0.29 | I24: =SUMIFS('January 2026 bills'!$I$11:$I$50,'January 2026 bills'!$L$11:$L$50,$A24) -> 8650 | J24: =I24*H24 -> 2508.5 | K24: =IF(OR(H24=0,$J$30=0),0,$B$14*J24/$J$30/H24) -> 573720.91 | L24: =K24*H24 -> 166379.06
A25: W26-06 | B25: facial_similarity_report_motion_ETSI_Certified_IDV_with_QES_and_OTP | C25: Motion (ETSI Certified IDV with QES and OTP) | D25: facial_similarity_report_motion | E25: All | F25: 1.36 | G25: =IF(F25=0,0,1-H25/F25) -> 0.78676471 | H25: 0.29 | I25: =SUMIFS('January 2026 bills'!$I$11:$I$50,'January 2026 bills'!$L$11:$L$50,$A25) -> 10615 | J25: =I25*H25 -> 3078.35 | K25: =IF(OR(H25=0,$J$30=0),0,$B$14*J25/$J$30/H25) -> 704051.73 | L25: =K25*H25 -> 204175
A26: W26-07 | B26: repeat_attempts_report_standard | C26: Repeat Attempts | D26: repeat_attempts_report_standard | E26: All | F26: 0 | G26: =IF(F26=0,0,1-H26/F26) -> 0 | H26: 0 | I26: =SUMIFS('January 2026 bills'!$I$11:$I$50,'January 2026 bills'!$L$11:$L$50,$A26) -> 7860 | J26: =I26*H26 -> 0 | K26: =IF(OR(H26=0,$J$30=0),0,$B$14*J26/$J$30/H26) -> 0 | L26: =K26*H26 -> 0
A27: W26-08 | B27: applicant_fraud_report_standard | C27: Device Intelligence - Standard | D27: applicant_fraud_report_standard | E27: All | F27: 0 | G27: =IF(F27=0,0,1-H27/F27) -> 0 | H27: 0 | I27: =SUMIFS('January 2026 bills'!$I$11:$I$50,'January 2026 bills'!$L$11:$L$50,$A27) -> 11447 | J27: =I27*H27 -> 0 | K27: =IF(OR(H27=0,$J$30=0),0,$B$14*J27/$J$30/H27) -> 0 | L27: =K27*H27 -> 0
A28: W26-09 | B28: known_faces_report_standard | C28: Facial Similarity Check Upgrade - Known Faces | D28: known_faces_report_standard | E28: All | F28: 0 | G28: =IF(F28=0,0,1-H28/F28) -> 0 | H28: 0 | I28: =SUMIFS('January 2026 bills'!$I$11:$I$50,'January 2026 bills'!$L$11:$L$50,$A28) -> 0 | J28: =I28*H28 -> 0 | K28: =IF(OR(H28=0,$J$30=0),0,$B$14*J28/$J$30/H28) -> 0 | L28: =K28*H28 -> 0
A29: W26-10 | B29: autofill | C29: OCR Autofill | D29: autofill | E29: All | F29: 0 | G29: =IF(F29=0,0,1-H29/F29) -> 0 | H29: 0 | I29: =SUMIFS('January 2026 bills'!$I$11:$I$50,'January 2026 bills'!$L$11:$L$50,$A29) -> 0 | J29: =I29*H29 -> 0 | K29: =IF(OR(H29=0,$J$30=0),0,$B$14*J29/$J$30/H29) -> 0 | L29: =K29*H29 -> 0
A30: Total | J30: =SUM(J20:J29) -> 10556.65 | L30: =SUM(L20:L29) -> 700181.6
A31: Illustrative annual value less minimum prepayment (EUR) | L31: =ROUND(L30-B14,2) -> 0
A33: Notes
A34: Illustrative annual volume splits the minimum prepayment across lines in proportion to January 2026 billed value, then divides by net price. The volumes actually quoted are not held in m3ter.
A35: Lines with no January 2026 usage get no illustrative volume.
A36: Lines priced at 0.00 are included at no charge.
A37: Minimum prepayment is the contract's usage ACV (customFields_nsUsageACV). On Wolt's 2026 contract that figure less the January drawdown equals the balance m3ter still holds (700,181.60 - 10,556.65 = 689,624.95).
A38: CSM fee commitment is customFields_CSMFeeCommitment on the contract. Empty is shown as 0.
A39: KAZ and SRB have no separate price on this quote. Those checks bill at the ANY price.
A40: Line W26-02 prices the JPN segment, but its accounting product in m3ter is named Document Check - USA.
A41: The quote total assumes the CSM fee is charged on top of the prepayment. m3ter records the amount only.
A42: The January 2026 volume covers 27 to 31 January only, the first five days of this contract.

Sheet January 2026 bills
A1: January 2026 bills recomputed from quote prices
A2: Billed quantities from m3ter, priced at the net prices on the quote tabs. Blue: values held in m3ter. Black: formulas. Green: formulas reading the quote tabs.
A3: Source: m3ter data in local Postgres (customerdb, schema entrust), queried by Claude on 6 Oct 2026. The queries are on the Data Sources tab. Bill totals in column G are from the m3ter bill screenshots the user shared on 6 Oct 2026.
A4: Line type summed | C4: USAGE | D4: USAGE | E4: BALANCE_CONSUMED
A5: Customer | B5: m3ter bill | C5: Usage at quote prices (EUR) | D5: Billed usage (EUR) | E5: Prepayment drawn down (EUR) | F5: Bill total recomputed (EUR) | G5: m3ter bill total (EUR) | H5: Difference (EUR)
A6: Signicat AS | B6: INV-6327 | C6: =SUMIFS($N$11:$N$50,$A$11:$A$50,$A6,$C$11:$C$50,C$4) -> 23747.86 | D6: =SUMIFS($K$11:$K$50,$A$11:$A$50,$A6,$C$11:$C$50,D$4) -> 23747.86 | E6: =SUMIFS($K$11:$K$50,$A$11:$A$50,$A6,$C$11:$C$50,E$4) -> -23747.86 | F6: =C6+E6 -> 0 | G6: 0 | H6: =ROUND(F6-G6,2) -> 0
A7: Wolt Enterprises Oy | B7: INV-74aa | C7: =SUMIFS($N$11:$N$50,$A$11:$A$50,$A7,$C$11:$C$50,C$4) -> 77519.99 | D7: =SUMIFS($K$11:$K$50,$A$11:$A$50,$A7,$C$11:$C$50,D$4) -> 77519.99 | E7: =SUMIFS($K$11:$K$50,$A$11:$A$50,$A7,$C$11:$C$50,E$4) -> -10556.65 | F7: =C7+E7 -> 66963.34 | G7: 66963.34 | H7: =ROUND(F7-G7,2) -> 0
A9: Bill lines
A10: Customer | B10: Opportunity | C10: Line type | D10: Accounting product | E10: m3ter meter | F10: Country segment | G10: Service period start | H10: Service period end | I10: Quantity | J10: Billed unit price (EUR) | K10: Billed subtotal (EUR) | L10: Quote line | M10: Quote net price (EUR) | N10: Recomputed subtotal (EUR) | O10: Difference (EUR) | P10: Note
A11: Signicat AS | B11: 006So00000KusqKIAR | C11: USAGE | D11: document_report_standard_hybrid | E11: document_report_standard_hybrid | G11: 46023 | H11: 46054 | I11: 16739 | J11: 0.77 | K11: 12889.03 | L11: S-01 | M11: {=INDEX('Signicat quote'!$H$20:$H$31,MATCH($L11,'Signicat quote'!$A$20:$A$31,0))} -> 0.77 | N11: =ROUND(I11*M11,2) -> 12889.03 | O11: =IF(C11="USAGE",N11-K11,0) -> 0
A12: Signicat AS | B12: 006So00000KusqKIAR | C12: USAGE | D12: document_report_standard_auto | E12: document_report_standard_auto | G12: 46023 | H12: 46054 | I12: 7220 | J12: 0.22 | K12: 1588.4 | L12: S-02 | M12: {=INDEX('Signicat quote'!$H$20:$H$31,MATCH($L12,'Signicat quote'!$A$20:$A$31,0))} -> 0.22 | N12: =ROUND(I12*M12,2) -> 1588.4 | O12: =IF(C12="USAGE",N12-K12,0) -> 0
A13: Signicat AS | B13: 006So00000KusqKIAR | C13: USAGE | D13: document_report_standard_manual | E13: document_report_standard_manual | G13: 46023 | H13: 46054 | I13: 5673 | J13: 0.77 | K13: 4368.21 | L13: S-03 | M13: {=INDEX('Signicat quote'!$H$20:$H$31,MATCH($L13,'Signicat quote'!$A$20:$A$31,0))} -> 0.77 | N13: =ROUND(I13*M13,2) -> 4368.21 | O13: =IF(C13="USAGE",N13-K13,0) -> 0
A14: Signicat AS | B14: 006So00000KusqKIAR | C14: USAGE | D14: document_report_driver_verification | E14: document_report_driver_verification | G14: 46023 | H14: 46054 | I14: 66 | J14: 0.77 | K14: 50.82 | L14: S-04 | M14: {=INDEX('Signicat quote'!$H$20:$H$31,MATCH($L14,'Signicat quote'!$A$20:$A$31,0))} -> 0.77 | N14: =ROUND(I14*M14,2) -> 50.82 | O14: =IF(C14="USAGE",N14-K14,0) -> 0
A15: Signicat AS | B15: 006So00000KusqKIAR | C15: USAGE | D15: facial_similarity_report_standard | E15: facial_similarity_report_standard | G15: 46023 | H15: 46054 | I15: 12970 | J15: 0.37 | K15: 4798.9 | L15: S-05 | M15: {=INDEX('Signicat quote'!$H$20:$H$31,MATCH($L15,'Signicat quote'!$A$20:$A$31,0))} -> 0.37 | N15: =ROUND(I15*M15,2) -> 4798.9 | O15: =IF(C15="USAGE",N15-K15,0) -> 0
A16: Signicat AS | B16: 006So00000KusqKIAR | C16: USAGE | D16: facial_similarity_report_video | E16: facial_similarity_report_video | G16: 46023 | H16: 46054 | I16: 70 | J16: 0.75 | K16: 52.5 | L16: S-06 | M16: {=INDEX('Signicat quote'!$H$20:$H$31,MATCH($L16,'Signicat quote'!$A$20:$A$31,0))} -> 0.75 | N16: =ROUND(I16*M16,2) -> 52.5 | O16: =IF(C16="USAGE",N16-K16,0) -> 0
A17: Signicat AS | B17: 006So00000KusqKIAR | C17: USAGE | D17: known_faces_report_standard | E17: known_faces_report_standard | G17: 46023 | H17: 46054 | I17: 2 | J17: 0 | K17: 0 | L17: S-09 | M17: {=INDEX('Signicat quote'!$H$20:$H$31,MATCH($L17,'Signicat quote'!$A$20:$A$31,0))} -> 0 | N17: =ROUND(I17*M17,2) -> 0 | O17: =IF(C17="USAGE",N17-K17,0) -> 0
A18: Signicat AS | B18: 006So00000KusqKIAR | C18: USAGE | D18: repeat_attempts_report_standard | E18: repeat_attempts_report_standard | G18: 46023 | H18: 46054 | I18: 27232 | J18: 0 | K18: 0 | L18: S-10 | M18: {=INDEX('Signicat quote'!$H$20:$H$31,MATCH($L18,'Signicat quote'!$A$20:$A$31,0))} -> 0 | N18: =ROUND(I18*M18,2) -> 0 | O18: =IF(C18="USAGE",N18-K18,0) -> 0
A19: Signicat AS | B19: 006So00000KusqKIAR | C19: BALANCE_CONSUMED | D19: minimum_prepayment | G19: 46023 | H19: 46054 | I19: 1 | J19: 0 | K19: -23747.86 | M19: 0 | N19: =ROUND(I19*M19,2) -> 0 | O19: =IF(C19="USAGE",N19-K19,0) -> 0 | P19: Prepayment drawdown
A20: Wolt Enterprises Oy | B20: 006So00000HLTq3IAH | C20: USAGE | D20: CPQ_ID_1223 | E20: document_report_standard_hybrid | G20: 46023 | H20: 46049 | I20: 34720 | J20: 0.63 | K20: 21873.6 | L20: W25-01 | M20: {=INDEX('Wolt quote 2025'!$H$20:$H$30,MATCH($L20,'Wolt quote 2025'!$A$20:$A$30,0))} -> 0.63 | N20: =ROUND(I20*M20,2) -> 21873.6 | O20: =IF(C20="USAGE",N20-K20,0) -> 0
A21: Wolt Enterprises Oy | B21: 006So00000HLTq3IAH | C21: USAGE | D21: CPQ_ID_1221 | E21: document_report_standard_hybrid | F21: JPN | G21: 46023 | H21: 46049 | I21: 1405 | J21: 1.2 | K21: 1686 | L21: W25-02 | M21: {=INDEX('Wolt quote 2025'!$H$20:$H$30,MATCH($L21,'Wolt quote 2025'!$A$20:$A$30,0))} -> 1.2 | N21: =ROUND(I21*M21,2) -> 1686 | O21: =IF(C21="USAGE",N21-K21,0) -> 0
A22: Wolt Enterprises Oy | B22: 006So00000HLTq3IAH | C22: USAGE | D22: CPQ_ID_1222 | E22: document_report_standard_hybrid | F22: KAZ | G22: 46023 | H22: 46049 | I22: 7290 | J22: 0.63 | K22: 4592.7 | L22: W25-03 | M22: {=INDEX('Wolt quote 2025'!$H$20:$H$30,MATCH($L22,'Wolt quote 2025'!$A$20:$A$30,0))} -> 0.63 | N22: =ROUND(I22*M22,2) -> 4592.7 | O22: =IF(C22="USAGE",N22-K22,0) -> 0
A23: Wolt Enterprises Oy | B23: 006So00000HLTq3IAH | C23: USAGE | D23: CPQ_ID_1222 | E23: document_report_standard_hybrid | F23: SRB | G23: 46023 | H23: 46049 | I23: 22 | J23: 0.63 | K23: 13.86 | L23: W25-03 | M23: {=INDEX('Wolt quote 2025'!$H$20:$H$30,MATCH($L23,'Wolt quote 2025'!$A$20:$A$30,0))} -> 0.63 | N23: =ROUND(I23*M23,2) -> 13.86 | O23: =IF(C23="USAGE",N23-K23,0) -> 0
A24: Wolt Enterprises Oy | B24: 006So00000HLTq3IAH | C24: USAGE | D24: document_report_standard_hybrid | E24: document_report_standard_hybrid | G24: 46023 | H24: 46049 | I24: 43437 | J24: 0 | K24: 0 | M24: 0 | N24: =ROUND(I24*M24,2) -> 0 | O24: =IF(C24="USAGE",N24-K24,0) -> 0 | P24: m3ter total-count line at 0.00, not a quote line
A25: Wolt Enterprises Oy | B25: 006So00000HLTq3IAH | C25: USAGE | D25: CPQ_ID_1298 | E25: document_report_driver_verification | G25: 46023 | H25: 46049 | I25: 3306 | J25: 0.63 | K25: 2082.78 | L25: W25-04 | M25: {=INDEX('Wolt quote 2025'!$H$20:$H$30,MATCH($L25,'Wolt quote 2025'!$A$20:$A$30,0))} -> 0.63 | N25: =ROUND(I25*M25,2) -> 2082.78 | O25: =IF(C25="USAGE",N25-K25,0) -> 0
A26: Wolt Enterprises Oy | B26: 006So00000HLTq3IAH | C26: USAGE | D26: document_report_driver_verification | E26: document_report_driver_verification | G26: 46023 | H26: 46049 | I26: 3306 | J26: 0 | K26: 0 | M26: 0 | N26: =ROUND(I26*M26,2) -> 0 | O26: =IF(C26="USAGE",N26-K26,0) -> 0 | P26: m3ter total-count line at 0.00, not a quote line
A27: Wolt Enterprises Oy | B27: 006So00000HLTq3IAH | C27: USAGE | D27: facial_similarity_report_standard | E27: facial_similarity_report_standard | G27: 46023 | H27: 46049 | I27: 45377 | J27: 0.4 | K27: 18150.8 | L27: W25-06 | M27: {=INDEX('Wolt quote 2025'!$H$20:$H$30,MATCH($L27,'Wolt quote 2025'!$A$20:$A$30,0))} -> 0.4 | N27: =ROUND(I27*M27,2) -> 18150.8 | O27: =IF(C27="USAGE",N27-K27,0) -> 0
A28: Wolt Enterprises Oy | B28: 006So00000HLTq3IAH | C28: USAGE | D28: facial_similarity_report_motion | E28: facial_similarity_report_motion | G28: 46023 | H28: 46049 | I28: 46409 | J28: 0.4 | K28: 18563.6 | L28: W25-07 | M28: {=INDEX('Wolt quote 2025'!$H$20:$H$30,MATCH($L28,'Wolt quote 2025'!$A$20:$A$30,0))} -> 0.4 | N28: =ROUND(I28*M28,2) -> 18563.6 | O28: =IF(C28="USAGE",N28-K28,0) -> 0
A29: Wolt Enterprises Oy | B29: 006So00000HLTq3IAH | C29: USAGE | D29: repeat_attempts_report_standard | E29: repeat_attempts_report_standard | G29: 46023 | H29: 46049 | I29: 41689 | J29: 0 | K29: 0 | L29: W25-08 | M29: {=INDEX('Wolt quote 2025'!$H$20:$H$30,MATCH($L29,'Wolt quote 2025'!$A$20:$A$30,0))} -> 0 | N29: =ROUND(I29*M29,2) -> 0 | O29: =IF(C29="USAGE",N29-K29,0) -> 0
A30: Wolt Enterprises Oy | B30: 006So00000HLTq3IAH | C30: USAGE | D30: applicant_fraud_report_standard | E30: applicant_fraud_report_standard | G30: 46023 | H30: 46049 | I30: 50028 | J30: 0 | K30: 0 | L30: W25-09 | M30: {=INDEX('Wolt quote 2025'!$H$20:$H$30,MATCH($L30,'Wolt quote 2025'!$A$20:$A$30,0))} -> 0 | N30: =ROUND(I30*M30,2) -> 0 | O30: =IF(C30="USAGE",N30-K30,0) -> 0
A31: Wolt Enterprises Oy | B31: 006So00000QJ9IPIA1 | C31: USAGE | D31: CPQ_ID_1218 | E31: document_report_standard_hybrid | G31: 46049 | H31: 46050 | I31: 1986 | J31: 0.54 | K31: 1072.44 | L31: W26-01 | M31: {=INDEX('Wolt quote 2026'!$H$20:$H$29,MATCH($L31,'Wolt quote 2026'!$A$20:$A$29,0))} -> 0.54 | N31: =ROUND(I31*M31,2) -> 1072.44 | O31: =IF(C31="USAGE",N31-K31,0) -> 0
A32: Wolt Enterprises Oy | B32: 006So00000QJ9IPIA1 | C32: USAGE | D32: CPQ_ID_1218 | E32: document_report_standard_hybrid | G32: 46050 | H32: 46054 | I32: 6041 | J32: 0.54 | K32: 3262.14 | L32: W26-01 | M32: {=INDEX('Wolt quote 2026'!$H$20:$H$29,MATCH($L32,'Wolt quote 2026'!$A$20:$A$29,0))} -> 0.54 | N32: =ROUND(I32*M32,2) -> 3262.14 | O32: =IF(C32="USAGE",N32-K32,0) -> 0
A33: Wolt Enterprises Oy | B33: 006So00000QJ9IPIA1 | C33: USAGE | D33: CPQ_ID_1219 | E33: document_report_standard_hybrid | F33: JPN | G33: 46049 | H33: 46050 | I33: 51 | J33: 1.2 | K33: 61.2 | L33: W26-02 | M33: {=INDEX('Wolt quote 2026'!$H$20:$H$29,MATCH($L33,'Wolt quote 2026'!$A$20:$A$29,0))} -> 1.2 | N33: =ROUND(I33*M33,2) -> 61.2 | O33: =IF(C33="USAGE",N33-K33,0) -> 0
A34: Wolt Enterprises Oy | B34: 006So00000QJ9IPIA1 | C34: USAGE | D34: CPQ_ID_1219 | E34: document_report_standard_hybrid | F34: JPN | G34: 46050 | H34: 46054 | I34: 198 | J34: 1.2 | K34: 237.6 | L34: W26-02 | M34: {=INDEX('Wolt quote 2026'!$H$20:$H$29,MATCH($L34,'Wolt quote 2026'!$A$20:$A$29,0))} -> 1.2 | N34: =ROUND(I34*M34,2) -> 237.6 | O34: =IF(C34="USAGE",N34-K34,0) -> 0
A35: Wolt Enterprises Oy | B35: 006So00000QJ9IPIA1 | C35: USAGE | D35: document_report_standard_hybrid | E35: document_report_standard_hybrid | G35: 46049 | H35: 46050 | I35: 2037 | J35: 0 | K35: 0 | M35: 0 | N35: =ROUND(I35*M35,2) -> 0 | O35: =IF(C35="USAGE",N35-K35,0) -> 0 | P35: m3ter total-count line at 0.00, not a quote line
A36: Wolt Enterprises Oy | B36: 006So00000QJ9IPIA1 | C36: USAGE | D36: document_report_standard_hybrid | E36: document_report_standard_hybrid | G36: 46050 | H36: 46054 | I36: 6239 | J36: 0 | K36: 0 | M36: 0 | N36: =ROUND(I36*M36,2) -> 0 | O36: =IF(C36="USAGE",N36-K36,0) -> 0 | P36: m3ter total-count line at 0.00, not a quote line
A37: Wolt Enterprises Oy | B37: 006So00000QJ9IPIA1 | C37: USAGE | D37: CPQ_ID_1298 | E37: document_report_driver_verification | G37: 46049 | H37: 46050 | I37: 173 | J37: 0.54 | K37: 93.42 | L37: W26-03 | M37: {=INDEX('Wolt quote 2026'!$H$20:$H$29,MATCH($L37,'Wolt quote 2026'!$A$20:$A$29,0))} -> 0.54 | N37: =ROUND(I37*M37,2) -> 93.42 | O37: =IF(C37="USAGE",N37-K37,0) -> 0
A38: Wolt Enterprises Oy | B38: 006So00000QJ9IPIA1 | C38: USAGE | D38: CPQ_ID_1298 | E38: document_report_driver_verification | G38: 46050 | H38: 46054 | I38: 450 | J38: 0.54 | K38: 243 | L38: W26-03 | M38: {=INDEX('Wolt quote 2026'!$H$20:$H$29,MATCH($L38,'Wolt quote 2026'!$A$20:$A$29,0))} -> 0.54 | N38: =ROUND(I38*M38,2) -> 243 | O38: =IF(C38="USAGE",N38-K38,0) -> 0
A39: Wolt Enterprises Oy | B39: 006So00000QJ9IPIA1 | C39: USAGE | D39: document_report_driver_verification | E39: document_report_driver_verification | G39: 46049 | H39: 46050 | I39: 173 | J39: 0 | K39: 0 | M39: 0 | N39: =ROUND(I39*M39,2) -> 0 | O39: =IF(C39="USAGE",N39-K39,0) -> 0 | P39: m3ter total-count line at 0.00, not a quote line
A40: Wolt Enterprises Oy | B40: 006So00000QJ9IPIA1 | C40: USAGE | D40: document_report_driver_verification | E40: document_report_driver_verification | G40: 46050 | H40: 46054 | I40: 450 | J40: 0 | K40: 0 | M40: 0 | N40: =ROUND(I40*M40,2) -> 0 | O40: =IF(C40="USAGE",N40-K40,0) -> 0 | P40: m3ter total-count line at 0.00, not a quote line
A41: Wolt Enterprises Oy | B41: 006So00000QJ9IPIA1 | C41: USAGE | D41: facial_similarity_report_standard | E41: facial_similarity_report_standard | G41: 46049 | H41: 46050 | I41: 2145 | J41: 0.29 | K41: 622.05 | L41: W26-05 | M41: {=INDEX('Wolt quote 2026'!$H$20:$H$29,MATCH($L41,'Wolt quote 2026'!$A$20:$A$29,0))} -> 0.29 | N41: =ROUND(I41*M41,2) -> 622.05 | O41: =IF(C41="USAGE",N41-K41,0) -> 0
...

Sheet Data Sources
A1: Written to | B1: Source | C1: Object | D1: Obtained via | E1: Query or request | F1: Parameters | G1: Run at | H1: Requested by | I1: Row count | J1: Changes after retrieval | K1: Notes
A2: 'Signicat quote'!A4:B15; 'Wolt quote 2025'!A4:B15; 'Wolt quote 2026'!A4:B15 | B2: m3ter data in local Postgres (customerdb, schema entrust) | C2: customerdb.entrust.contracts, accounts, accountplans, plans, plantemplates | D2: Read-only SQL through the Postgres MCP server, run by Claude | E2: SELECT a.name AS account, a.code AS account_code, c.code AS opportunity, c."startDate", c."endDate", c."customFields_contractLength" AS term_months, c."customFields_nsUsageACV" AS usage_acv, c."customFields_CSMFeeCommitment" AS csm_fee, p.code AS plan_code, p.name AS plan_name, pt.name AS rate_card, pt."billFrequency" AS bill_frequency, pt.currency FROM entrust.contracts c JOIN entrust.accounts a ON a.id = c."accountId" JOIN entrust.accountplans ap ON ap."contractId" = c.id JOIN entrust.plans p ON p.id = ap."planId" JOIN entrust.plantemplates pt ON pt.id = p."planTemplateId" WHERE a.code IN ('0012400000bYaokAAC','0012400001GbKtsAAF') ORDER BY a.name, c."startDate" | F2: None | G2: 2026-10-06 17:12 IST (UTC+01:00) | H2: John Griffin | I2: 3 | J2: One row per quote tab, laid out as label and value. Quote type taken from the plan name. Empty CSM fee shown as 0.
A3: 'Signicat quote'!A19:H31; 'Wolt quote 2025'!A19:H30; 'Wolt quote 2026'!A19:H29 (columns A to E and H) | B3: m3ter data in local Postgres (customerdb, schema entrust) | C3: customerdb.entrust.plans, pricings, aggregations, meters, products | D3: Read-only SQL through the Postgres MCP server, run by Claude | E3: SELECT p.code AS plan_code, m.code AS meter, pr."segmentString" AS segment, ap.code AS accounting_product, ap.name AS accounting_product_name, (pr."pricingBands"::jsonb->0->>'unitPrice')::numeric AS unit_price, jsonb_array_length(pr."pricingBands"::jsonb) AS bands FROM entrust.plans p JOIN entrust.pricings pr ON pr."planId" = p.id JOIN entrust.aggregations ag ON ag.id = pr."aggregationId" JOIN entrust.meters m ON m.id = ag."meterId" LEFT JOIN entrust.products ap ON ap.id = pr."accountingProductId" WHERE p.code IN ('checks_006So00000HLTq3IAH','checks_006So00000QJ9IPIA1','checks_006So00000KusqKIAR') AND NOT (ag."segmentedFields"::text IN ('[]','null') AND ag."customFields_opportunityId" IS NULL AND m.code IN ('document_report_standard_hybrid','document_report_driver_verification') AND p.code <> 'checks_006So00000KusqKIAR') ORDER BY 1, 2, 3 | F3: None | G3: 2026-10-06 17:12 IST (UTC+01:00) | H3: John Griffin | I3: 34 | J3: Split by plan into the three quote tabs. KAZ and SRB segment prices merged into one line (W25-03). Line ids added. Products with no accounting product on the pricing use the product code shown on the bill.
A4: 'Signicat quote'!F20:F31; 'Wolt quote 2025'!F20:F30; 'Wolt quote 2026'!F20:F29 | B4: m3ter data in local Postgres (customerdb, schema entrust) | C4: customerdb.entrust.plantemplates, pricings, aggregations, meters | D4: Read-only SQL through the Postgres MCP server, run by Claude | E4: SELECT m.code AS meter, (pr."pricingBands"::jsonb->0->>'unitPrice')::numeric AS list_price, pr."startDate" FROM entrust.plantemplates pt JOIN entrust.pricings pr ON pr."planTemplateId" = pt.id JOIN entrust.aggregations ag ON ag.id = pr."aggregationId" JOIN entrust.meters m ON m.id = ag."meterId" WHERE pt.code = 'rate_card_b_eur_default_pricing' AND pr."endDate" IS NULL AND m.code IN ('document_report_standard_hybrid','document_report_standard_auto','document_report_standard_manual','document_report_driver_verification','facial_similarity_report_standard','facial_similarity_report_motion','facial_similarity_report_video','proof_of_address_report_standard','repeat_attempts_report_standard','applicant_fraud_report_standard','autofill','known_faces_report_standard') ORDER BY 1 | F4: None | G4: 2026-10-06 17:12 IST (UTC+01:00) | H4: John Griffin | I4: 12 | J4: Matched to quote lines by meter. | K4: Prices in force from 27 Jan 2025 with no end date.
A5: 'January 2026 bills'!A10:K50 | B5: m3ter data in local Postgres (customerdb, schema entrust) | C5: customerdb.entrust.bills (lineItems), plans, meters | D5: Read-only SQL through the Postgres MCP server, run by Claude | E5: SELECT b."accountCode" AS account_code, li->>'lineItemType' AS type, p.code AS plan_code, m.code AS meter, li->'segment'->>'country' AS country, li->>'accountingProductCode' AS accounting_product, left(li->>'servicePeriodStartDate', 10) AS period_start, left(li->>'servicePeriodEndDate', 10) AS period_end, (li->>'quantity')::numeric AS quantity, (li->>'averageUnitPrice')::numeric AS unit_price, (li->>'subtotal')::numeric AS subtotal FROM entrust.bills b CROSS JOIN LATERAL jsonb_array_elements(b."lineItems"::jsonb) li LEFT JOIN entrust.plans p ON p.id = li->>'planId' LEFT JOIN entrust.meters m ON m.id = li->>'meterId' WHERE b.id IN ('e8d28b4f-4e61-460d-8525-7f2bc8b974aa','ce9c574e-9384-46f5-8f9d-d4d4c5906327') AND ((li->>'quantity')::numeric > 0 OR (li->>'subtotal')::numeric <> 0) ORDER BY 1, 3, 4, 5, 7 | F5: None | G5: 2026-10-06 17:12 IST (UTC+01:00) | H5: John Griffin | I5: 40 | J5: Account code shown as customer name, plan code as opportunity. Rows reordered. Quote line and Note columns added.
A6: 'January 2026 bills'!G6:G7 | B6: m3ter bill details screens | C6: Bills INV-6327 and INV-74aa | D6: Screenshots pasted into chat by user; not read from m3ter by Claude | E6: ok lets take the 2 bills in m3ter for the accounts you have listed above | F6: None | G6: 2026-10-06 (screenshots show bills last calculated 9 Apr 2026) | H6: John Griffin | I6: 2 | J6: None | K6: Used because billTotal in customerdb is rounded to whole numbers.
